Workbook

Sheet Rundown
A1: PETRA x DANAMON — International Banking Immersion Program
A2: RUNDOWN PROGRAM — 1 Minggu di Surabaya, Indonesia
A3: Pilot Cohort | Peserta Jepang + Mahasiswa PETRA | Minggu (Arrival) – Sabtu (Departure)
A5: Hari | B5: Waktu | C5: Aktivitas | D5: Lokasi | E5: PIC | F5: Keterangan
A6: MINGGU — Day 0 | ARRIVAL DAY
A7: MINGGU | B7: 12.00–17.00 | C7: Kedatangan peserta di Bandara Juanda (SUB) | D7: Bandara Juanda | E7: LO Team | F7: Penjemputan bertahap sesuai jadwal penerbangan
A8: MINGGU | B8: 17.00–18.00 | C8: Transfer ke hotel & check-in | D8: Hotel | E8: LO Team | F8: Pembagian kamar (twin share)
A9: MINGGU | B9: 18.30–20.00 | C9: Welcome dinner ringan & briefing program | D9: Hotel | E9: Panitia | F9: Pembagian buddy, name tag & welcome kit
A10: MINGGU | B10: 20.00 | C10: Istirahat | D10: Hotel | E10: — | F10: Free evening
A11: SENIN — Day 1 | OPENING & PERKENALAN
A12: SENIN | B12: 08.00–08.30 | C12: Transfer hotel → kampus PETRA | D12: — | E12: LO Team
A13: SENIN | B13: 09.00–10.30 | C13: Opening Ceremony — sambutan Rektor PETRA & perwakilan Danamon | D13: Auditorium PETRA | E13: Panitia | F13: Foto bersama & press moment
A14: SENIN | B14: 10.30–11.00 | C14: Coffee break | D14: PETRA | E14: —
A15: SENIN | B15: 11.00–12.00 | C15: Program overview & ice breaking | D15: Auditorium PETRA | E15: Fasilitator | F15: Penjelasan alur capstone
A16: SENIN | B16: 12.00–13.00 | C16: Lunch | D16: PETRA | E16: —
A17: SENIN | B17: 13.00–15.00 | C17: Team building & pembentukan kelompok capstone | D17: PETRA | E17: Fasilitator | F17: Peserta Jepang + lokal dicampur
A18: SENIN | B18: 15.00–16.00 | C18: Buddy time / pengenalan kampus ringan | D18: PETRA | E18: Buddy
A19: SENIN | B19: 16.00 | C19: Kembali ke hotel | D19: — | E19: LO Team
A20: SELASA — Day 2 | LECTURES (PETRA) + CAMPUS TOUR
A21: SELASA | B21: 08.30–09.00 | C21: Transfer ke kampus | D21: — | E21: LO Team
A22: SELASA | B22: 09.00–10.30 | C22: Lecture 1: Indonesian Economy & Banking Ecosystem Overview | D22: Ruang Kelas SBM | E22: Narasumber PETRA
A23: SELASA | B23: 10.30–10.45 | C23: Coffee break | D23: PETRA | E23: —
A24: SELASA | B24: 10.45–12.15 | C24: Lecture 2: Financial System & Business Management in Indonesia | D24: Ruang Kelas SBM | E24: Narasumber PETRA
A25: SELASA | B25: 12.15–13.15 | C25: Lunch | D25: PETRA | E25: —
A26: SELASA | B26: 13.15–15.00 | C26: Campus Tour PETRA (fasilitas, lab, student center) | D26: Kampus PETRA | E26: Buddy / LO
A27: SELASA | B27: 15.00–16.00 | C27: Diskusi & refleksi harian | D27: PETRA | E27: Fasilitator | F27: Progress check capstone
A28: SELASA | B28: 16.00 | C28: Kembali ke hotel | D28: — | E28: LO Team
A29: RABU — Day 3 | LECTURES (DANAMON) + SITE VISIT
A30: RABU | B30: 08.00–08.45 | C30: Transfer ke Kantor Bank Danamon | D30: — | E30: LO Team
A31: RABU | B31: 09.00–10.30 | C31: Lecture: Digital Banking & Indonesian Banking Industry | D31: Kantor Danamon | E31: Eksekutif Danamon
A32: RABU | B32: 10.30–10.45 | C32: Coffee break | D32: Danamon | E32: —
A33: RABU | B33: 10.45–12.00 | C33: Office tour & site visit Bank Danamon | D33: Kantor Danamon | E33: Danamon Host | F33: Lihat operasional & unit kerja
A34: RABU | B34: 12.00–13.00 | C34: Lunch (hosted by Danamon) | D34: Danamon | E34: Danamon | F34: Indikatif — dikonfirmasi
A35: RABU | B35: 13.00–15.00 | C35: Interactive workshop / case sharing & Q&A | D35: Kantor Danamon | E35: Danamon
A36: RABU | B36: 15.00–16.00 | C36: Transfer kembali / persiapan | D36: — | E36: LO Team
A37: RABU | B37: 16.00 | C37: Kembali ke hotel | D37: — | E37: LO Team
A38: KAMIS — Day 4 | CITY TOUR & CULTURAL IMMERSION
A39: KAMIS | B39: 08.00–08.30 | C39: Transfer | D39: — | E39: LO Team
A40: KAMIS | B40: 08.30–11.00 | C40: Surabaya City Tour (Tugu Pahlawan, Kampung Maspati/Peneleh, Kota Lama) | D40: Pusat Kota Surabaya | E40: Tour Guide
A41: KAMIS | B41: 11.00–13.00 | C41: Batik Class (cultural immersion) + Lunch lokal | D41: Sanggar Batik | E41: Instruktur | F41: Karya batik dibawa pulang peserta
...

Sheet RAB
A1: RANCANGAN ANGGARAN BELANJA (RAB)
A2: PETRA x DANAMON International Banking Immersion Program — Pilot Cohort
A4: No | B4: Uraian | C4: Volume | D4: Satuan | E4: Frekuensi | F4: Harga Satuan (Rp) | G4: Jumlah (Rp) | H4: Keterangan
A5: A. AKOMODASI
A6: 1 | B6: Hotel peserta (twin share) | C6: =Asumsi!$B$9 -> 10 | D6: kamar | E6: =Asumsi!$B$7 -> 6 | F6: 650000 | G6: =C6*E6*F6 -> 39000000 | H6: Bintang 3–4, termasuk breakfast
A7: 2 | B7: Hotel pendamping / dosen Jepang | C7: 5 | D7: kamar | E7: =Asumsi!$B$7 -> 6 | F7: 650000 | G7: =C7*E7*F7 -> 19500000 | H7: Opsional
B8: Subtotal A | G8: =SUM(G6:G7) -> 58500000
A10: B. TRANSPORTASI
A11: 3 | B11: Airport transfer (pickup & drop) | C11: 2 | D11: trip | E11: 1 | F11: 1500000 | G11: =C11*E11*F11 -> 3000000 | H11: Bus + koordinasi LO
A12: 4 | B12: Bus operasional harian | C12: 1 | D12: bus | E12: 5 | F12: 1800000 | G12: =C12*E12*F12 -> 9000000 | H12: Senin–Jumat
A13: 5 | B13: BBM, tol, parkir & meal driver | C13: 1 | D13: paket | E13: 5 | F13: 300000 | G13: =C13*E13*F13 -> 1500000 | H13: Per hari operasional
B14: Subtotal B | G14: =SUM(G11:G13) -> 13500000
A16: C. KONSUMSI
A17: 6 | B17: Makan siang peserta Jepang | C17: =Asumsi!$B$3 -> 20 | D17: pax | E17: 5 | F17: 50000 | G17: =C17*E17*F17 -> 5000000 | H17: Hari kerja (sebagian dapat di-host)
A18: 7 | B18: Makan malam peserta Jepang (non-acara) | C18: =Asumsi!$B$3 -> 20 | D18: pax | E18: 4 | F18: 110000 | G18: =C18*E18*F18 -> 8800000 | H18: Min, Sel, Rab, Kam
A19: 8 | B19: Coffee break sesi lecture | C19: =Asumsi!$B$5 -> 70 | D19: pax | E19: 3 | F19: 35000 | G19: =C19*E19*F19 -> 7350000 | H19: Sel, Rab, Jum (2 sesi/hari)
A20: 9 | B20: Makan siang peserta lokal (sesi bersama) | C20: 50 | D20: pax | E20: 3 | F20: 50000 | G20: =C20*E20*F20 -> 7500000 | H20: Opsional — dapat dihapus
B21: Subtotal C | G21: =SUM(G17:G20) -> 28650000
A23: D. AKADEMIK & SERTIFIKAT
A24: 10 | B24: Honorarium / token narasumber PETRA | C24: 4 | D24: sesi | E24: 1 | F24: 1000000 | G24: =C24*E24*F24 -> 4000000 | H24: 2 dosen x 2 sesi
A25: 11 | B25: Token / plakat narasumber Danamon | C25: 1 | D25: paket | E25: 1 | F25: 2500000 | G25: =C25*E25*F25 -> 2500000 | H25: Cendera mata
A26: 12 | B26: Sewa ruang/aula & peralatan AV | C26: 1 | D26: paket | E26: 3 | F26: 1500000 | G26: =C26*E26*F26 -> 4500000 | H26: Hari lecture
A27: 13 | B27: Sertifikat co-branded | C27: =Asumsi!$B$5 -> 70 | D27: pax | E27: 1 | F27: 25000 | G27: =C27*E27*F27 -> 1750000 | H27: PETRA + Danamon
A28: 14 | B28: Seminar kit & materi | C28: =Asumsi!$B$5 -> 70 | D28: pax | E28: 1 | F28: 50000 | G28: =C28*E28*F28 -> 3500000 | H28: Modul, notebook, pen
B29: Subtotal D | G29: =SUM(G24:G28) -> 16250000
A31: E. AKTIVITAS & KULTURAL
A32: 15 | B32: Surabaya City Tour (guide + tiket masuk) | C32: =Asumsi!$B$5 -> 70 | D32: pax | E32: 1 | F32: 150000 | G32: =C32*E32*F32 -> 10500000
A33: 16 | B33: Batik class (instruktur + bahan) | C33: =Asumsi!$B$5 -> 70 | D33: pax | E33: 1 | F33: 100000 | G33: =C33*E33*F33 -> 7000000 | H33: Termasuk kain & alat
A34: 17 | B34: Wonorejo Mangrove Tour (perahu + tiket) | C34: =Asumsi!$B$5 -> 70 | D34: pax | E34: 1 | F34: 125000 | G34: =C34*E34*F34 -> 8750000
B35: Subtotal E | G35: =SUM(G32:G34) -> 26250000
A37: F. ACARA (OPENING / CLOSING / FAREWELL)
A38: 18 | B38: Opening ceremony (dekor, sound, MC, snack) | C38: 1 | D38: paket | E38: 1 | F38: 8000000 | G38: =C38*E38*F38 -> 8000000 | H38: Untuk seluruh tamu
A39: 19 | B39: Welcome dinner (Minggu) | C39: =Asumsi!$B$3 -> 20 | D39: pax | E39: 1 | F39: 100000 | G39: =C39*E39*F39 -> 2000000
A40: 20 | B40: Closing party + farewell dinner (catering) | C40: =Asumsi!$B$5 -> 70 | D40: pax | E40: 1 | F40: 150000 | G40: =C40*E40*F40 -> 10500000 | H40: Peserta + tamu undangan
A41: 21 | B41: Dekorasi & hiburan closing | C41: 1 | D41: paket | E41: 1 | F41: 6000000 | G41: =C41*E41*F41 -> 6000000 | H41: Panggung, band/MC
A42: 22 | B42: Hadiah & sertifikat capstone | C42: 1 | D42: paket | E42: 1 | F42: 3000000 | G42: =C42*E42*F42 -> 3000000 | H42: Best team awards
B43: Subtotal F | G43: =SUM(G38:G42) -> 29500000
A45: G. MERCHANDISE & DOKUMENTASI
A46: 23 | B46: Welcome kit / goodie bag | C46: =Asumsi!$B$5 -> 70 | D46: pax | E46: 1 | F46: 100000 | G46: =C46*E46*F46 -> 7000000 | H46: Tote, lanyard, booklet
A47: 24 | B47: Program apparel (t-shirt) | C47: =Asumsi!$B$5 -> 70 | D47: pax | E47: 1 | F47: 80000 | G47: =C47*E47*F47 -> 5600000
...

Sheet Asumsi
A1: ASUMSI & PARAMETER PERENCANAAN
A2: Parameter | B2: Nilai | C2: Catatan
A3: Peserta Jepang (funded cohort) | B3: 20 | C3: Range pilot 15–20 — ubah sesuai final
A4: Peserta Lokal (PCU) | B4: 50 | C4: Hadir di lecture, kultural & acara
A5: Total Peserta | B5: =B3+B4 -> 70 | C5: Otomatis
A6: Pendamping / Dosen Jepang | B6: 10 | C6: Opsional
A7: Jumlah Malam Menginap | B7: 6 | C7: Minggu–Jumat (check-out Sabtu)
A8: Peserta per Kamar (twin share) | B8: 2
A9: Jumlah Kamar Peserta | B9: =ROUNDUP(B3/B8,0) -> 10 | C9: Otomatis
A10: Contingency (%) | B10: 0.1 | C10: Cadangan tak terduga
A11: Kurs referensi (info, IDR per USD) | B11: 16300 | C11: Hanya untuk konversi indikatif
